<?xml version="1.0" ?>
<robot name="partnet_76a7e00101f52c70e413b5309d4fbd97">
	<link name="base"/>
	<link name="link_0">
		<visual name="door_frame-18">
			<origin xyz="-0.3807878965770184 -0.7201900000000003 -0.3004950962124482"/>
			<geometry>
				<mesh filename="textured_objs/new-4.obj"/>
			</geometry>
		</visual>
		<visual name="door_frame-18">
			<origin xyz="-0.3807878965770184 -0.7201900000000003 -0.3004950962124482"/>
			<geometry>
				<mesh filename="textured_objs/original-8.obj"/>
			</geometry>
		</visual>
		<visual name="handle-19">
			<origin xyz="-0.3807878965770184 -0.7201900000000003 -0.3004950962124482"/>
			<geometry>
				<mesh filename="textured_objs/original-1.obj"/>
			</geometry>
		</visual>
		<collision>
			<origin xyz="-0.3807878965770184 -0.7201900000000003 -0.3004950962124482"/>
			<geometry>
				<mesh filename="textured_objs/new-4.obj"/>
			</geometry>
		</collision>
		<collision>
			<origin xyz="-0.3807878965770184 -0.7201900000000003 -0.3004950962124482"/>
			<geometry>
				<mesh filename="textured_objs/original-8.obj"/>
			</geometry>
		</collision>
		<collision>
			<origin xyz="-0.3807878965770184 -0.7201900000000003 -0.3004950962124482"/>
			<geometry>
				<mesh filename="textured_objs/original-1.obj"/>
			</geometry>
		</collision>
	</link>
	<joint name="joint_0" type="revolute">
		<origin xyz="0.3807878965770184 0.7201900000000003 0.3004950962124482"/>
		<axis xyz="0 1 0"/>
		<child link="link_0"/>
		<parent link="link_1"/>
		<limit lower="-0.0" upper="3.141592653589793"/>
	</joint>
	<link name="link_1">
		<visual name="frame-11">
			<origin xyz="0 0 0"/>
			<geometry>
				<mesh filename="textured_objs/new-6.obj"/>
			</geometry>
		</visual>
		<visual name="foot-4">
			<origin xyz="0 0 0"/>
			<geometry>
				<mesh filename="textured_objs/original-16.obj"/>
			</geometry>
		</visual>
		<visual name="foot-4">
			<origin xyz="0 0 0"/>
			<geometry>
				<mesh filename="textured_objs/new-2.obj"/>
			</geometry>
		</visual>
		<visual name="foot-5">
			<origin xyz="0 0 0"/>
			<geometry>
				<mesh filename="textured_objs/new-1.obj"/>
			</geometry>
		</visual>
		<visual name="foot-6">
			<origin xyz="0 0 0"/>
			<geometry>
				<mesh filename="textured_objs/new-0.obj"/>
			</geometry>
		</visual>
		<visual name="foot-7">
			<origin xyz="0 0 0"/>
			<geometry>
				<mesh filename="textured_objs/new-3.obj"/>
			</geometry>
		</visual>
		<visual name="foot-7">
			<origin xyz="0 0 0"/>
			<geometry>
				<mesh filename="textured_objs/original-7.obj"/>
			</geometry>
		</visual>
		<collision>
			<origin xyz="0 0 0"/>
			<geometry>
				<mesh filename="textured_objs/new-6.obj"/>
			</geometry>
		</collision>
		<collision>
			<origin xyz="0 0 0"/>
			<geometry>
				<mesh filename="textured_objs/original-16.obj"/>
			</geometry>
		</collision>
		<collision>
			<origin xyz="0 0 0"/>
			<geometry>
				<mesh filename="textured_objs/new-2.obj"/>
			</geometry>
		</collision>
		<collision>
			<origin xyz="0 0 0"/>
			<geometry>
				<mesh filename="textured_objs/new-1.obj"/>
			</geometry>
		</collision>
		<collision>
			<origin xyz="0 0 0"/>
			<geometry>
				<mesh filename="textured_objs/new-0.obj"/>
			</geometry>
		</collision>
		<collision>
			<origin xyz="0 0 0"/>
			<geometry>
				<mesh filename="textured_objs/new-3.obj"/>
			</geometry>
		</collision>
		<collision>
			<origin xyz="0 0 0"/>
			<geometry>
				<mesh filename="textured_objs/original-7.obj"/>
			</geometry>
		</collision>
	</link>
	<joint name="joint_1" type="fixed">
		<origin rpy="1.570796326794897 0 -1.570796326794897" xyz="0 0 0"/>
		<child link="link_1"/>
		<parent link="base"/>
	</joint>
	<link name="link_2">
		<visual name="other_leaf-15">
			<origin xyz="-0.3807878965770184 -0.7201900000000003 -0.3004950962124482"/>
			<geometry>
				<mesh filename="textured_objs/original-20.obj"/>
			</geometry>
		</visual>
		<visual name="other_leaf-15">
			<origin xyz="-0.3807878965770184 -0.7201900000000003 -0.3004950962124482"/>
			<geometry>
				<mesh filename="textured_objs/original-30.obj"/>
			</geometry>
		</visual>
		<visual name="other_leaf-15">
			<origin xyz="-0.3807878965770184 -0.7201900000000003 -0.3004950962124482"/>
			<geometry>
				<mesh filename="textured_objs/original-31.obj"/>
			</geometry>
		</visual>
		<visual name="other_leaf-15">
			<origin xyz="-0.3807878965770184 -0.7201900000000003 -0.3004950962124482"/>
			<geometry>
				<mesh filename="textured_objs/original-23.obj"/>
			</geometry>
		</visual>
		<visual name="other_leaf-15">
			<origin xyz="-0.3807878965770184 -0.7201900000000003 -0.3004950962124482"/>
			<geometry>
				<mesh filename="textured_objs/original-24.obj"/>
			</geometry>
		</visual>
		<visual name="other_leaf-15">
			<origin xyz="-0.3807878965770184 -0.7201900000000003 -0.3004950962124482"/>
			<geometry>
				<mesh filename="textured_objs/original-25.obj"/>
			</geometry>
		</visual>
		<visual name="other_leaf-15">
			<origin xyz="-0.3807878965770184 -0.7201900000000003 -0.3004950962124482"/>
			<geometry>
				<mesh filename="textured_objs/original-26.obj"/>
			</geometry>
		</visual>
		<visual name="other_leaf-15">
			<origin xyz="-0.3807878965770184 -0.7201900000000003 -0.3004950962124482"/>
			<geometry>
				<mesh filename="textured_objs/original-27.obj"/>
			</geometry>
		</visual>
		<visual name="other_leaf-15">
			<origin xyz="-0.3807878965770184 -0.7201900000000003 -0.3004950962124482"/>
			<geometry>
				<mesh filename="textured_objs/original-28.obj"/>
			</geometry>
		</visual>
		<visual name="other_leaf-15">
			<origin xyz="-0.3807878965770184 -0.7201900000000003 -0.3004950962124482"/>
			<geometry>
				<mesh filename="textured_objs/original-29.obj"/>
			</geometry>
		</visual>
		<visual name="door_frame-16">
			<origin xyz="-0.3807878965770184 -0.7201900000000003 -0.3004950962124482"/>
			<geometry>
				<mesh filename="textured_objs/new-5.obj"/>
			</geometry>
		</visual>
		<visual name="door_frame-16">
			<origin xyz="-0.3807878965770184 -0.7201900000000003 -0.3004950962124482"/>
			<geometry>
				<mesh filename="textured_objs/original-9.obj"/>
			</geometry>
		</visual>
		<visual name="handle-17">
			<origin xyz="-0.3807878965770184 -0.7201900000000003 -0.3004950962124482"/>
			<geometry>
				<mesh filename="textured_objs/original-5.obj"/>
			</geometry>
		</visual>
		<visual name="handle-17">
			<origin xyz="-0.3807878965770184 -0.7201900000000003 -0.3004950962124482"/>
			<geometry>
				<mesh filename="textured_objs/original-4.obj"/>
			</geometry>
		</visual>
		<collision>
			<origin xyz="-0.3807878965770184 -0.7201900000000003 -0.3004950962124482"/>
			<geometry>
				<mesh filename="textured_objs/original-20.obj"/>
			</geometry>
		</collision>
		<collision>
			<origin xyz="-0.3807878965770184 -0.7201900000000003 -0.3004950962124482"/>
			<geometry>
				<mesh filename="textured_objs/original-30.obj"/>
			</geometry>
		</collision>
		<collision>
			<origin xyz="-0.3807878965770184 -0.7201900000000003 -0.3004950962124482"/>
			<geometry>
				<mesh filename="textured_objs/original-31.obj"/>
			</geometry>
		</collision>
		<collision>
			<origin xyz="-0.3807878965770184 -0.7201900000000003 -0.3004950962124482"/>
			<geometry>
				<mesh filename="textured_objs/original-23.obj"/>
			</geometry>
		</collision>
		<collision>
			<origin xyz="-0.3807878965770184 -0.7201900000000003 -0.3004950962124482"/>
			<geometry>
				<mesh filename="textured_objs/original-24.obj"/>
			</geometry>
		</collision>
		<collision>
			<origin xyz="-0.3807878965770184 -0.7201900000000003 -0.3004950962124482"/>
			<geometry>
				<mesh filename="textured_objs/original-25.obj"/>
			</geometry>
		</collision>
		<collision>
			<origin xyz="-0.3807878965770184 -0.7201900000000003 -0.3004950962124482"/>
			<geometry>
				<mesh filename="textured_objs/original-26.obj"/>
			</geometry>
		</collision>
		<collision>
			<origin xyz="-0.3807878965770184 -0.7201900000000003 -0.3004950962124482"/>
			<geometry>
				<mesh filename="textured_objs/original-27.obj"/>
			</geometry>
		</collision>
		<collision>
			<origin xyz="-0.3807878965770184 -0.7201900000000003 -0.3004950962124482"/>
			<geometry>
				<mesh filename="textured_objs/original-28.obj"/>
			</geometry>
		</collision>
		<collision>
			<origin xyz="-0.3807878965770184 -0.7201900000000003 -0.3004950962124482"/>
			<geometry>
				<mesh filename="textured_objs/original-29.obj"/>
			</geometry>
		</collision>
		<collision>
			<origin xyz="-0.3807878965770184 -0.7201900000000003 -0.3004950962124482"/>
			<geometry>
				<mesh filename="textured_objs/new-5.obj"/>
			</geometry>
		</collision>
		<collision>
			<origin xyz="-0.3807878965770184 -0.7201900000000003 -0.3004950962124482"/>
			<geometry>
				<mesh filename="textured_objs/original-9.obj"/>
			</geometry>
		</collision>
		<collision>
			<origin xyz="-0.3807878965770184 -0.7201900000000003 -0.3004950962124482"/>
			<geometry>
				<mesh filename="textured_objs/original-5.obj"/>
			</geometry>
		</collision>
		<collision>
			<origin xyz="-0.3807878965770184 -0.7201900000000003 -0.3004950962124482"/>
			<geometry>
				<mesh filename="textured_objs/original-4.obj"/>
			</geometry>
		</collision>
	</link>
	<joint name="joint_2" type="revolute">
		<origin xyz="0.3807878965770184 0.7201900000000003 0.3004950962124482"/>
		<axis xyz="0 1 0"/>
		<child link="link_2"/>
		<parent link="link_1"/>
		<limit lower="-0.0" upper="3.141592653589793"/>
	</joint>
</robot>
