<?xml version="1.0" ?>
<robot name="partnet_1b7d468a27208ee3dad910e221d16b18">
	<link name="base"/>
	<link name="link_0">
		<visual name="cover_lid-5">
			<origin xyz="0.011088999999999988 -0.7329289999999999 0"/>
			<geometry>
				<mesh filename="textured_objs/original-2.obj"/>
			</geometry>
		</visual>
		<visual name="cover_support-6">
			<origin xyz="0.011088999999999988 -0.7329289999999999 0"/>
			<geometry>
				<mesh filename="textured_objs/original-1.obj"/>
			</geometry>
		</visual>
		<collision>
			<origin xyz="0.011088999999999988 -0.7329289999999999 0"/>
			<geometry>
				<mesh filename="textured_objs/original-2.obj"/>
			</geometry>
		</collision>
		<collision>
			<origin xyz="0.011088999999999988 -0.7329289999999999 0"/>
			<geometry>
				<mesh filename="textured_objs/original-1.obj"/>
			</geometry>
		</collision>
	</link>
	<joint name="joint_0" type="revolute">
		<origin xyz="-0.011088999999999988 0.7329289999999999 0"/>
		<axis xyz="1 0 0"/>
		<child link="link_0"/>
		<parent link="link_1"/>
		<limit lower="-1.8221237390820801" upper="1.2252211349000193"/>
	</joint>
	<link name="link_1">
		<visual name="container_box-3">
			<origin xyz="0 0 0"/>
			<geometry>
				<mesh filename="textured_objs/new-1.obj"/>
			</geometry>
		</visual>
		<visual name="container_bottom-4">
			<origin xyz="0 0 0"/>
			<geometry>
				<mesh filename="textured_objs/new-0.obj"/>
			</geometry>
		</visual>
		<collision>
			<origin xyz="0 0 0"/>
			<geometry>
				<mesh filename="textured_objs/new-1.obj"/>
			</geometry>
		</collision>
		<collision>
			<origin xyz="0 0 0"/>
			<geometry>
				<mesh filename="textured_objs/new-0.obj"/>
			</geometry>
		</collision>
	</link>
	<joint name="joint_1" type="fixed">
		<origin rpy="1.570796326794897 0 -1.570796326794897" xyz="0 0 0"/>
		<child link="link_1"/>
		<parent link="base"/>
	</joint>
</robot>
